<?xml version="1.0"?>
<robot name="wheel" xmlns:xacro="http://www.ros.org/wiki/xacro">

  <!-- Wheels -->
<!--
  <xacro:property name="wheel_radius" value="0.125" />
  <xacro:property name="wheel_height" value="0.032" />
-->
  <xacro:property name="wheel_mass" value="0.3" /> <!-- in kg-->

<!--
  <xacro:property name="base_x_origin_to_wheel_origin" value="0.25" />
  <xacro:property name="base_y_origin_to_wheel_origin" value="0.3" />
  <xacro:property name="base_z_origin_to_wheel_origin" value="0.0" />
-->

  <xacro:macro name="cylinder_inertia" params="m r h">
    <inertia ixx="${m*(3*r*r+h*h)/12}" ixy="0" ixz="0"
             iyy="${m*(3*r*r+h*h)/12}" iyz="0"
             izz="${m*r*r/2}" />
  </xacro:macro>

  <xacro:macro name="wheel"
               params="fb lr parent translateX translateY translateZ wheel_radius wheel_height flip"> <!--fb : front, back ; lr: left, right -->
    <link name="${fb}_${lr}_wheel">

    <visual>
      <origin
        xyz="0 0 0"
        rpy="0 0 0" />
      <geometry>
        <mesh
          filename="package://unicorn_description/meshes/wheel_driver.STL" />
      </geometry>
      <material
        name="">
        <color
          rgba="0.752941176470588 0.752941176470588 0.752941176470588 1" />
      </material>
    </visual>

    <collision>
      <origin
        xyz="0 0 0"
        rpy="0 0 0" />
      <geometry>
        <mesh
          filename="package://unicorn_description/meshes/wheel_driver.STL" />
      </geometry>
    </collision>

    <inertial>
      <origin
        xyz="-6.0591E-12 -0.012242 1.8648E-11"
        rpy="0 0 0" />
      <mass
        value="1.0564" />
      <inertia
        ixx="0.0040937"
        ixy="3.2935E-14"
        ixz="-4.4864E-13"
        iyy="0.008088"
        iyz="-6.8807E-12"
        izz="0.0040937" />
    </inertial>

    </link>

<!--
    <gazebo reference="${fb}_${lr}_wheel">
      <mu1 value="100.0" />
      <mu2 value="100.0" />
      <kp value="1000.0" />
      <kd value="1.0" />
      <fdir1 value="1 0 0" />
      <material>Gazebo/Black</material>
      <turnGravityOff>false</turnGravityOff>
    </gazebo>-->

    <joint name="${fb}_${lr}_wheel_joint" type="continuous">
      <parent link="${parent}" />
      <child link="${fb}_${lr}_wheel" />
      <origin xyz="${translateX} ${translateY} ${translateZ}" rpy="0 0 0" />
      <axis xyz="0 1 0" rpy="0 0 0" />
      <limit effort="1000" velocity="100" />
      <joint_properties damping="0.0" friction="0.0" />
    </joint>

    <!-- Transmission is important to link the joints and the controller -->
    <transmission name="${fb}_${lr}_wheel_joint_trans">
      <type>transmission_interface/SimpleTransmission</type>
      <joint name="${fb}_${lr}_wheel_joint">
        <hardwareInterface>hardware_interface/EffortJointInterface</hardwareInterface>
      </joint>
      <actuator name="${fb}_${lr}_wheel_joint_motor">
        <hardwareInterface>hardware_interface/EffortJointInterface</hardwareInterface>
        <mechanicalReduction>1</mechanicalReduction>
      </actuator>
    </transmission>

  </xacro:macro>
</robot>
